Workbook

Sheet Leia-me
A1: EMPREENDER+ — Estudo de Viabilidade Financeira
A2: Versão 1.0 · 27 de julho de 2026 · Documento preliminar para discussão entre sócios
A4: COMO USAR ESTA PLANILHA
A5: Células amarelas com texto azul | B5: São as premissas que você pode e deve editar. Todo o resto é fórmula e recalcula sozinho.
A6: Células pretas | B6: Fórmulas. Não edite — elas dependem das premissas.
A7: Aba Premissas | B7: Centraliza todos os direcionadores do modelo: câmbio, preços, custo de IA, churn, CAC.
A9: ABAS
A10: Premissas | B10: Todos os direcionadores do modelo, com a fonte de cada número.
A11: Investimento Inicial | B11: O que precisa ser desembolsado antes do lançamento, e o custo de desenvolvimento como referência.
A12: Custos Fixos | B12: Infraestrutura e operação, escalonados por faixa de assinantes.
A13: Unit Economics | B13: Quanto sobra de cada assinatura, LTV, CAC e payback. É a aba mais importante.
A14: Projecao 24 meses | B14: Três cenários mês a mês: conservador, realista e otimista.
A15: Ponto de Equilibrio | B15: Quantos assinantes pagam a conta e em quanto tempo o investimento retorna.
A16: Fontes | B16: Origem de cada número de mercado usado no modelo.
A18: AVISOS IMPORTANTES
A19: Premissas, não previsões | B19: Nenhum número aqui é garantido. O valor da planilha está em mostrar quais variáveis decidem o resultado.
A20: As três variáveis críticas | B20: 1) custo de IA por assinante 2) churn mensal 3) CAC. Uma variação pequena em qualquer uma delas muda o resultado inteiro.
A21: Não é aconselhamento financeiro | B21: Este é um modelo de trabalho. Valide os números fiscais com seu contador antes de tomar decisões.

Sheet Premissas
A1: Premissas do Modelo
A2: Edite apenas as células amarelas. A coluna Fonte explica de onde veio cada número.
A4: Premissa | B4: Valor | C4: Fonte / justificativa
A5: CÂMBIO E CARGA FISCAL
A6: Câmbio USD → BRL | B6: 5.08 | C6: Cotação de 27/07/2026 (Investing.com). Revise periodicamente.
A7: Imposto sobre receita (Simples Nacional) | B7: 0.06 | C7: Anexo III, 1ª faixa (até R$ 180 mil/ano). Sobe conforme o faturamento — confirme com o contador.
A8: Taxa do gateway de pagamento | B8: 0.044 | C8: Stripe Brasil: 3,99% nacional + 0,4% para assinatura recorrente.
A9: Comissão das lojas de aplicativo | B9: 0.15 | C9: Apple/Google Small Business Program: 15% para faturamento abaixo de US$ 1 mi/ano.
A10: % das assinaturas cobradas dentro do app | B10: 0.3 | C10: PREMISSA CRÍTICA: quanto maior, menor a margem. Cobrar pela web evita a comissão.
A12: PREÇOS E MIX DE PLANOS
A13: Plano Básico (R$/mês) | B13: 19.9 | C13: Definido por você.
A14: Plano Premium (R$/mês) | B14: 29.9 | C14: Definido por você.
A15: % dos assinantes no plano Básico | B15: 0.7 | C15: Premissa. Em SaaS B2C, o plano de entrada costuma concentrar 65% a 80% da base.
A16: Receita média por assinante (ARPU) | B16: =B15*B13+(1-B15)*B14 -> 22.9 | C16: Calculado.
A18: CUSTO DE INTELIGÊNCIA ARTIFICIAL
A19: Interações com o copiloto por assinante/mês | B19: 60 | C19: Premissa de uso. Um assinante ativo em pleno workflow. Ajuste após medir o uso real.
A20: Tokens de entrada por interação | B20: 8000 | C20: Contexto do negócio + memória + playbook do nicho + pergunta.
A21: Tokens de saída por interação | B21: 1200 | C21: Resposta do copiloto.
A22: % das chamadas no modelo econômico | B22: 0.7 | C22: Roteamento: perguntas simples no modelo barato, etapas críticas no modelo avançado.
A23: Modelo econômico — entrada (US$/1M tokens) | B23: 1 | C23: Claude Haiku 4.5, julho/2026.
A24: Modelo econômico — saída (US$/1M tokens) | B24: 5 | C24: Claude Haiku 4.5, julho/2026.
A25: Modelo avançado — entrada (US$/1M tokens) | B25: 3 | C25: Claude Sonnet, julho/2026.
A26: Modelo avançado — saída (US$/1M tokens) | B26: 15 | C26: Claude Sonnet, julho/2026.
A27: Economia obtida com cache de prompt | B27: 0.35 | C27: Cache reduz até 90% do custo de entrada repetida. 35% é uma estimativa conservadora do efeito líquido.
A28: Custo de IA por assinante Básico (R$/mês) | B28: =((B19*B20/1000000)*(B22*B23+(1-B22)*B25)*(1-B27)+(B19*B21/1000000)*(B22*B24+(1-B22)*B26))*B6 -> 5.462016 | C28: Calculado a partir das premissas acima. É a variável nº 1 do modelo.
A29: Multiplicador de uso do plano Premium | B29: 1.7 | C29: Premium usa mais módulos e mais IA.
A30: Custo de IA por assinante Premium (R$/mês) | B30: =B28*B29 -> 9.2854272 | C30: Calculado.
A32: FUNIL GRATUITO E AQUISIÇÃO
A33: Cadastros gratuitos por assinante pago | B33: 12 | C33: Conversão implícita de ~8%. É o custo do diagnóstico gratuito que você oferece.
A34: Custo de IA por diagnóstico gratuito (R$) | B34: 0.18 | C34: Diagnóstico é majoritariamente cálculo; a IA só redige a explicação.
A35: Custo do funil gratuito por assinante pago (R$) | B35: =B33*B34 -> 2.16 | C35: Calculado.
A36: CAC — custo de aquisição por assinante (R$) | B36: 120 | C36: PREMISSA CRÍTICA. Tráfego pago para SaaS B2C no Brasil. Canal orgânico e parcerias reduzem muito.
A37: % dos novos assinantes vindos de canal pago | B37: 0.5 | C37: O restante vem de orgânico, indicação, parcerias e white label — que não consomem CAC.
A38: Churn mensal | B38: 0.07 | C38: PREMISSA CRÍTICA. SaaS B2C de baixo ticket costuma ficar entre 5% e 10% ao mês.
A39: Vida média do assinante (meses) | B39: =IF(B38=0,0,1/B38) -> 14.285714 | C39: Calculado: 1 ÷ churn.

Sheet Investimento Inicial
A1: Investimento Inicial
A2: O que precisa sair do caixa antes do lançamento. Desenvolvimento entra à parte, como referência de mercado.
A4: Item | B4: Valor (R$) | C4: Observação
A5: A. DESEMBOLSO REAL — PRÉ-LANÇAMENTO
A6: Abertura da empresa (ME/Simples) e honorários iniciais | B6: 1500 | C6: Registro na Junta, CNPJ, alvará e contrato social.
A7: Registro de domínio .com.br e .com (1 ano) | B7: 150 | C7: Registro.br cobra ~R$ 40/ano pelo .com.br.
A8: E-mail profissional — Google Workspace, 2 contas, 12 meses | B8: 878 | C8: US$ 7,20/usuário/mês × 2 × 12 × câmbio.
A9: Apple Developer Program (1 ano) | B9: 503 | C9: US$ 99/ano — renovação anual obrigatória.
A10: Google Play Console (taxa única) | B10: 127 | C10: US$ 25, pagamento único, sem renovação.
A11: Registro de marca no INPI (1 classe, com assessoria) | B11: 1800 | C11: Guia oficial + honorários. Essencial antes de investir em marketing.
A12: Identidade visual e design de marca | B12: 5000 | C12: Logo, paleta, aplicações, design do produto.
A13: Assessoria jurídica (Termos de Uso, Privacidade, LGPD) | B13: 2500 | C13: Obrigatório: você trata dados pessoais sensíveis no diagnóstico.
A14: Infraestrutura durante o desenvolvimento (6 meses) | B14: 1200 | C14: Supabase e Vercel em plano pago durante o build.
A15: Ferramentas de desenvolvimento e IA (6 meses) | B15: 3000 | C15: Editor com IA, Figma, repositório, ferramentas de apoio.
A16: Créditos de API de IA para desenvolvimento e testes | B16: 2000 | C16: Prototipagem dos prompts, avaliações e testes de carga.
A17: Curadoria da base de nichos (8 nichos no MVP) | B17: 12000 | C17: O ativo mais defensável do produto. Pesquisa e validação com especialistas por nicho.
A18: Subtotal | B18: =SUM(B6:B17) -> 30658
A19: Contingência (15%) | B19: =B18*0.15 -> 4598.7
A20: TOTAL DE DESEMBOLSO PRÉ-LANÇAMENTO | B20: =B18+B19 -> 35256.7
A22: B. DESENVOLVIMENTO — REFERÊNCIA DE MERCADO (não desembolsado: você desenvolve)
A23: Cenário | B23: Valor (R$) | C23: Escopo
A24: MVP enxuto (web responsiva + apps híbridos) | B24: 150000 | C24: ~1.100 h. Diagnóstico, workflow das trilhas A–C, copiloto, cobrança.
A25: Produto completo (referência central) | B25: 220000 | C25: ~1.500 h. Tudo acima + entregáveis, dossiê, painel administrativo e apps nativos.
A26: Produto completo com módulos de operação | B26: 320000 | C26: ~2.200 h. Inclui marketing, financeiro e hub B2B.
A27: Fonte: software houses brasileiras praticam de R$ 60 mil (MVP enxuto) a R$ 300 mil+ (produto completo) em 2026. Ver aba Fontes.
A29: C. MARKETING — SOMENTE APÓS O PRODUTO PRONTO
A30: Fase | B30: Valor (R$) | C30: Observação
A31: Pré-lançamento (landing, conteúdo, materiais, lista de espera) | B31: 5000 | C31: Desembolso único, 30 a 60 dias antes do lançamento.
A32: Meses 1 a 3 — validação de canal | B32: 6000 | C32: Por mês. Objetivo é descobrir o CAC real, não escalar.
A33: Meses 4 a 12 — escala controlada | B33: 12000 | C33: Por mês. Só aumente depois que a relação LTV/CAC fechar.
A34: Total de marketing no ano 1 | B34: =B31+B32*3+B33*9 -> 131000
A36: RESUMO
A37: Caixa necessário para chegar ao lançamento | B37: =B20 -> 35256.7 | C37: Sem contar o seu trabalho de desenvolvimento.
A38: Caixa necessário para os 12 primeiros meses (com marketing) | B38: =B20+B34 -> 166256.7 | C38: Investimento inicial + marketing do ano 1. Não inclui os custos fixos mensais, que estão na projeção.
A39: Valor equivalente do seu trabalho (capital investido em forma de trabalho) | B39: =B25 -> 220000 | C39: Referência central de desenvolvimento. Relevante na conversa de participação societária.

Sheet Custos Fixos
A1: Custos Fixos Mensais por Faixa de Assinantes
A2: A infraestrutura escala em degraus, não linearmente. Edite os valores em amarelo conforme a realidade.
A4: Item | B4: Até 500 | C4: 501 a 2.000 | D4: 2.001 a 10.000 | E4: Acima de 10.000 | F4: Observação
A5: CUSTOS EM DÓLAR (convertidos pelo câmbio da aba Premissas)
A6: Supabase (banco de dados, auth, storage) | B6: 25 | C6: 60 | D6: 180 | E6: 599 | F6: Pro = US$ 25 com compute Micro. Instâncias maiores e egress elevam a conta. Team = US$ 599.
A7: Vercel (hospedagem do sistema web) | B7: 20 | C7: 45 | D7: 150 | E7: 500 | F7: Pro = US$ 20/assento com 1 TB. Excedente a US$ 0,15/GB.
A8: E-mail transacional | B8: 0 | C8: 20 | D8: 50 | E8: 100 | F8: Resend/Postmark. Gratuito no início.
A9: Google Workspace (e-mail profissional) | B9: 14.4 | C9: 21.6 | D9: 36 | E9: 72 | F9: US$ 7,20 por conta/mês.
A10: Apple Developer (rateio mensal) | B10: 8.25 | C10: 8.25 | D10: 8.25 | E10: 8.25 | F10: US$ 99/ano ÷ 12.
A11: Monitoramento e observabilidade | B11: 0 | C11: 26 | D11: 80 | E11: 200 | F11: Sentry/Logs. Gratuito no início.
A12: Armazenamento e CDN adicionais | B12: 0 | C12: 10 | D12: 60 | E12: 250 | F12: Documentos gerados, imagens, exportações.
A13: Subtotal em US$ | B13: =SUM(B6:B12) -> 67.65 | C13: =SUM(C6:C12) -> 190.85 | D13: =SUM(D6:D12) -> 564.25 | E13: =SUM(E6:E12) -> 1729.25
A14: Subtotal em R$ | B14: =B13*Premissas!$B$6 -> 343.662 | C14: =C13*Premissas!$B$6 -> 969.518 | D14: =D13*Premissas!$B$6 -> 2866.39 | E14: =E13*Premissas!$B$6 -> 8784.59
A16: CUSTOS EM REAIS
A17: Contabilidade | B17: 350 | C17: 450 | D17: 700 | E17: 1200 | F17: Escritório contábil para Simples Nacional.
A18: Ferramentas de desenvolvimento e produtividade | B18: 200 | C18: 300 | D18: 500 | E18: 800 | F18: Editor com IA, design, gestão.
A19: Suporte e atendimento ao assinante | B19: 0 | C19: 800 | D19: 3000 | E19: 9000 | F19: Você atende no início; a partir de ~500 assinantes vira função dedicada.
A20: Subtotal em R$ | B20: =SUM(B17:B19) -> 550 | C20: =SUM(C17:C19) -> 1550 | D20: =SUM(D17:D19) -> 4200 | E20: =SUM(E17:E19) -> 11000
A22: TOTAL DE CUSTO FIXO (R$/mês) | B22: =B14+B20 -> 893.662 | C22: =C14+C20 -> 2519.518 | D22: =D14+D20 -> 7066.39 | E22: =E14+E20 -> 19784.59
A24: TABELA DE CONSULTA (usada pela projeção)
A25: Assinantes a partir de | B25: Faixa | C25: Custo fixo (R$/mês)
A26: 0 | B26: Até 500 assinantes | C26: =B22 -> 893.662
A27: 501 | B27: 501 a 2.000 assinantes | C27: =C22 -> 2519.518
A28: 2001 | B28: 2.001 a 10.000 assinantes | C28: =D22 -> 7066.39
A29: 10001 | B29: Acima de 10.000 assinantes | C29: =E22 -> 19784.59

Sheet Unit Economics
A1: Economia por Assinante
A2: Quanto sobra de cada assinatura depois de todos os custos que variam com o número de usuários.
A4: Linha | B4: Plano Básico | C4: Plano Premium | D4: Média ponderada | E4: Observação
A5: Receita bruta mensal | B5: =Premissas!$B$13 -> 19.9 | C5: =Premissas!$B$14 -> 29.9 | D5: =Premissas!$B$15*B5+(1-Premissas!$B$15)*C5 -> 22.9 | E5: Preço de tabela.
A6: (-) Impostos sobre receita | B6: =-B5*Premissas!$B$7 -> -1.194 | C6: =-C5*Premissas!$B$7 -> -1.794 | D6: =Premissas!$B$15*B6+(1-Premissas!$B$15)*C6 -> -1.374 | E6: Simples Nacional.
A7: (-) Taxa de gateway (parte cobrada na web) | B7: =-B5*(1-Premissas!$B$10)*Premissas!$B$8 -> -0.61292 | C7: =-C5*(1-Premissas!$B$10)*Premissas!$B$8 -> -0.92092 | D7: =Premissas!$B$15*B7+(1-Premissas!$B$15)*C7 -> -0.70532 | E7: Só incide sobre a parcela cobrada fora das lojas.
A8: (-) Comissão das lojas de aplicativo | B8: =-B5*Premissas!$B$10*Premissas!$B$9 -> -0.8955 | C8: =-C5*Premissas!$B$10*Premissas!$B$9 -> -1.3455 | D8: =Premissas!$B$15*B8+(1-Premissas!$B$15)*C8 -> -1.0305 | E8: 15% sobre a parcela cobrada dentro do app. Cobrar pela web elimina esta linha.
A9: (-) Custo de inteligência artificial | B9: =-Premissas!$B$28 -> -5.462016 | C9: =-Premissas!$B$30 -> -9.2854272 | D9: =Premissas!$B$15*B9+(1-Premissas!$B$15)*C9 -> -6.6090394 | E9: A maior despesa variável. Ver premissas de IA.
A10: (-) Custo do funil gratuito rateado | B10: =-Premissas!$B$35 -> -2.16 | C10: =-Premissas!$B$35 -> -2.16 | D10: =Premissas!$B$15*B10+(1-Premissas!$B$15)*C10 -> -2.16 | E10: Diagnósticos gratuitos que não converteram, rateados por assinante pago.
A11: MARGEM DE CONTRIBUIÇÃO | B11: =SUM(B5:B10) -> 9.575564 | C11: =SUM(C5:C10) -> 14.394153 | D11: =Premissas!$B$15*B11+(1-Premissas!$B$15)*C11 -> 11.021141 | E11: O que sobra de cada assinante para pagar custos fixos, marketing e lucro.
A12: Margem de contribuição (%) | B12: =B11/B5 -> 0.48118412 | C12: =C11/C5 -> 0.48140979 | D12: =D11/D5 -> 0.48127252 | E12: Saudável em SaaS: acima de 70%. Abaixo de 50% acende alerta.
A14: VALOR DO CLIENTE E RETORNO DA AQUISIÇÃO
A15: Vida média do assinante (meses) | D15: =Premissas!$B$39 -> 14.285714 | E15: 1 ÷ churn mensal.
A16: LTV — valor total gerado por assinante (R$) | D16: =D11*Premissas!$B$39 -> 157.44487 | E16: Margem de contribuição × vida média.
A17: CAC — custo de aquisição (R$) | D17: =Premissas!$B$36 -> 120
A18: Relação LTV / CAC | D18: =IF(D17=0,0,D16/D17) -> 1.3120406 | E18: Referência do setor: abaixo de 1,0x o negócio perde dinheiro a cada cliente; 3,0x ou mais é saudável.
A19: Payback do CAC (meses) | D19: =IF(D11=0,0,D17/D11) -> 10.888165 | E19: Quantos meses o assinante leva para pagar o custo de tê-lo conquistado. Acima de 12 é arriscado com churn alto.
A21: DIAGNÓSTICO AUTOMÁTICO
A22: Situação da relação LTV/CAC | B22: =IF(D18>=3,"SAUDÁVEL — aquisição paga se sustenta",IF(D18>=1.5,"APERTADO — só cresça com canal orgânico e parcerias","INVIÁVEL — cada cliente pago destrói caixa. Reduza custo de IA, churn ou CAC.")) -> INVIÁVEL — cada cliente pago destrói caixa. Reduza custo de IA, churn ou CAC.
A23: Receita necessária por assinante para LTV/CAC = 3,0x | B23: =(3*D17*Premissas!$B$38) + (D5-D11) -> 37.078859 | E23: Preço médio que tornaria a aquisição paga sustentável, mantendo churn e custos atuais.

Sheet Projecao 24 meses
A1: Projeção de 24 Meses — Três Cenários
A2: Edite apenas 'Novos assinantes no mês 1' e 'Crescimento mensal' de cada cenário. O resto recalcula.
A4: CENÁRIO CONSERVADOR
A5: Novos assinantes no mês 1 | B5: 15 | D5: Crescimento mensal de novos assinantes | E5: 0.12
A6: Mês | B6: M1 | C6: M2 | D6: M3 | E6: M4 | F6: M5 | G6: M6 | H6: M7 | I6: M8 | J6: M9 | K6: M10 | L6: M11 | M6: M12 | N6: M13 | O6: M14 | P6: M15 | Q6: M16 | R6: M17 | S6: M18 | T6: M19 | U6: M20 | V6: M21 | W6: M22 | X6: M23 | Y6: M24
A7: Novos assinantes | B7: =$B$5 -> 15 | C7: =B7*(1+$E$5) -> 16.8 | D7: =C7*(1+$E$5) -> 18.816 | E7: =D7*(1+$E$5) -> 21.07392 | F7: =E7*(1+$E$5) -> 23.60279 | G7: =F7*(1+$E$5) -> 26.435125 | H7: =G7*(1+$E$5) -> 29.60734 | I7: =H7*(1+$E$5) -> 33.160221 | J7: =I7*(1+$E$5) -> 37.139448 | ... Y7: =X7*(1+$E$5) -> 203.28521
A8: Base no início do mês | B8: =0 -> 0 | C8: =B10 -> 15 | D8: =C10 -> 30.75 | E8: =D10 -> 47.4135 | F8: =E10 -> 65.168475 | G8: =F10 -> 84.209472 | H8: =G10 -> 104.74993 | I8: =H10 -> 127.02478 | J8: =I10 -> 151.29327 | ... Y8: =X10 -> 1055.0475
A9: Cancelamentos | B9: =-B8*Premissas!$B$38 -> 0 | C9: =-C8*Premissas!$B$38 -> -1.05 | D9: =-D8*Premissas!$B$38 -> -2.1525 | E9: =-E8*Premissas!$B$38 -> -3.318945 | F9: =-F8*Premissas!$B$38 -> -4.5617933 | G9: =-G8*Premissas!$B$38 -> -5.8946631 | H9: =-H8*Premissas!$B$38 -> -7.3324954 | I9: =-I8*Premissas!$B$38 -> -8.8917345 | ... Y9: =-Y8*Premissas!$B$38 -> -73.853328
A10: Base no fim do mês | B10: =B8+B9+B7 -> 15 | C10: =C8+C9+C7 -> 30.75 | D10: =D8+D9+D7 -> 47.4135 | E10: =E8+E9+E7 -> 65.168475 | F10: =F8+F9+F7 -> 84.209472 | G10: =G8+G9+G7 -> 104.74993 | H10: =H8+H9+H7 -> 127.02478 | I10: =I8+I9+I7 -> 151.29327 | ... Y10: =Y8+Y9+Y7 -> 1184.4794
A11: Base média do mês | B11: =(B8+B10)/2 -> 7.5 | C11: =(C8+C10)/2 -> 22.875 | D11: =(D8+D10)/2 -> 39.08175 | E11: =(E8+E10)/2 -> 56.290987 | F11: =(F8+F10)/2 -> 74.688974 | G11: =(G8+G10)/2 -> 94.479703 | H11: =(H8+H10)/2 -> 115.88736 | I11: =(I8+I10)/2 -> 139.15902 | ... Y11: =(Y8+Y10)/2 -> 1119.7635
A12: Receita bruta | B12: =B11*Premissas!$B$16 -> 171.75 | C12: =C11*Premissas!$B$16 -> 523.8375 | D12: =D11*Premissas!$B$16 -> 894.97208 | E12: =E11*Premissas!$B$16 -> 1289.0636 | F12: =F11*Premissas!$B$16 -> 1710.3775 | G12: =G11*Premissas!$B$16 -> 2163.5852 | H12: =H11*Premissas!$B$16 -> 2653.8205 | I12: =I11*Premissas!$B$16 -> 3186.7416 | ... Y12: =Y11*Premissas!$B$16 -> 25642.584
A13: (-) Custos variáveis (impostos, taxas, IA, funil) | B13: =-B11*('Unit Economics'!$D$5-'Unit Economics'!$D$11) -> -89.091445 | C13: =-C11*('Unit Economics'!$D$5-'Unit Economics'!$D$11) -> -271.72891 | D13: =-D11*('Unit Economics'!$D$5-'Unit Economics'!$D$11) -> -464.24661 | E13: =-E11*('Unit Economics'!$D$5-'Unit Economics'!$D$11) -> -668.67272 | F13: =-F11*('Unit Economics'!$D$5-'Unit Economics'!$D$11) -> -887.21981 | G13: =-G11*('Unit Economics'!$D$5-'Unit Economics'!$D$11) -> -1122.3111 | H13: =-H11*('Unit Economics'!$D$5-'Unit Economics'!$D$11) -> -1376.6096 | I13: =-I11*('Unit Economics'!$D$5-'Unit Economics'!$D$11) -> -1653.0505 | ... Y13: =-Y11*('Unit Economics'!$D$5-'Unit Economics'!$D$11) -> -13301.513
A14: Margem de contribuição | B14: =B12+B13 -> 82.658555 | C14: =C12+C13 -> 252.10859 | D14: =D12+D13 -> 430.72546 | E14: =E12+E13 -> 620.39089 | F14: =F12+F13 -> 823.15768 | G14: =G12+G13 -> 1041.2741 | H14: =H12+H13 -> 1277.2109 | I14: =I12+I13 -> 1533.6912 | ... Y14: =Y12+Y13 -> 12341.071
A15: (-) Custos fixos | B15: =-INDEX('Custos Fixos'!$C$26:$C$29,MATCH(B10,'Custos Fixos'!$A$26:$A$29,1)) -> -893.662 | C15: =-INDEX('Custos Fixos'!$C$26:$C$29,MATCH(C10,'Custos Fixos'!$A$26:$A$29,1)) -> -893.662 | D15: =-INDEX('Custos Fixos'!$C$26:$C$29,MATCH(D10,'Custos Fixos'!$A$26:$A$29,1)) -> -893.662 | E15: =-INDEX('Custos Fixos'!$C$26:$C$29,MATCH(E10,'Custos Fixos'!$A$26:$A$29,1)) -> -893.662 | F15: =-INDEX('Custos Fixos'!$C$26:$C$29,MATCH(F10,'Custos Fixos'!$A$26:$A$29,1)) -> -893.662 | G15: =-INDEX('Custos Fixos'!$C$26:$C$29,MATCH(G10,'Custos Fixos'!$A$26:$A$29,1)) -> -893.662 | H15: =-INDEX('Custos Fixos'!$C$26:$C$29,MATCH(H10,'Custos Fixos'!$A$26:$A$29,1)) -> -893.662 | I15: =-INDEX('Custos Fixos'!$C$26:$C$29,MATCH(I10,'Custos Fixos'!$A$26:$A$29,1)) -> -893.662 | ... Y15: =-INDEX('Custos Fixos'!$C$26:$C$29,MATCH(Y10,'Custos Fixos'!$A$26:$A$29,1)) -> -2519.518
A16: (-) Marketing (novos × % canal pago × CAC) | B16: =-B7*Premissas!$B$37*Premissas!$B$36 -> -900 | C16: =-C7*Premissas!$B$37*Premissas!$B$36 -> -1008 | D16: =-D7*Premissas!$B$37*Premissas!$B$36 -> -1128.96 | E16: =-E7*Premissas!$B$37*Premissas!$B$36 -> -1264.4352 | F16: =-F7*Premissas!$B$37*Premissas!$B$36 -> -1416.1674 | G16: =-G7*Premissas!$B$37*Premissas!$B$36 -> -1586.1075 | H16: =-H7*Premissas!$B$37*Premissas!$B$36 -> -1776.4404 | I16: =-I7*Premissas!$B$37*Premissas!$B$36 -> -1989.6133 | ... Y16: =-Y7*Premissas!$B$37*Premissas!$B$36 -> -12197.113
A17: Resultado do mês | B17: =B14+B15+B16 -> -1711.0034 | C17: =C14+C15+C16 -> -1649.5534 | D17: =D14+D15+D16 -> -1591.8965 | E17: =E14+E15+E16 -> -1537.7063 | F17: =F14+F15+F16 -> -1486.6717 | G17: =G14+G15+G16 -> -1438.4954 | H17: =H14+H15+H16 -> -1392.8916 | I17: =I14+I15+I16 -> -1349.5841 | ... Y17: =Y14+Y15+Y16 -> -2375.5597
A18: Caixa acumulado | B18: =B17 -> -1711.0034 | C18: =B18+C17 -> -3360.5569 | D18: =C18+D17 -> -4952.4534 | E18: =D18+E17 -> -6490.1597 | F18: =E18+F17 -> -7976.8314 | G18: =F18+G17 -> -9415.3269 | H18: =G18+H17 -> -10808.218 | I18: =H18+I17 -> -12157.803 | J18: =I18+J17 -> -13466.107 | ... Y18: =X18+Y17 -> -41713.459
A21: CENÁRIO REALISTA
A22: Novos assinantes no mês 1 | B22: 40 | D22: Crescimento mensal de novos assinantes | E22: 0.15
A23: Mês | B23: M1 | C23: M2 | D23: M3 | E23: M4 | F23: M5 | G23: M6 | H23: M7 | I23: M8 | J23: M9 | K23: M10 | L23: M11 | M23: M12 | N23: M13 | O23: M14 | P23: M15 | Q23: M16 | R23: M17 | S23: M18 | T23: M19 | U23: M20 | V23: M21 | W23: M22 | X23: M23 | Y23: M24
A24: Novos assinantes | B24: =$B$22 -> 40 | C24: =B24*(1+$E$22) -> 46 | D24: =C24*(1+$E$22) -> 52.9 | E24: =D24*(1+$E$22) -> 60.835 | F24: =E24*(1+$E$22) -> 69.96025 | G24: =F24*(1+$E$22) -> 80.454288 | H24: =G24*(1+$E$22) -> 92.522431 | I24: =H24*(1+$E$22) -> 106.4008 | J24: =I24*(1+$E$22) -> 122.36091 | ... Y24: =X24*(1+$E$22) -> 995.6583
A25: Base no início do mês | B25: =0 -> 0 | C25: =B27 -> 40 | D25: =C27 -> 83.2 | E25: =D27 -> 130.276 | F25: =E27 -> 181.99168 | G25: =F27 -> 239.21251 | H25: =G27 -> 302.92192 | I25: =H27 -> 374.23982 | J25: =I27 -> 454.44383 | ... Y25: =X27 -> 4491.4629
A26: Cancelamentos | B26: =-B25*Premissas!$B$38 -> 0 | C26: =-C25*Premissas!$B$38 -> -2.8 | D26: =-D25*Premissas!$B$38 -> -5.824 | E26: =-E25*Premissas!$B$38 -> -9.11932 | F26: =-F25*Premissas!$B$38 -> -12.739418 | G26: =-G25*Premissas!$B$38 -> -16.744876 | H26: =-H25*Premissas!$B$38 -> -21.204535 | I26: =-I25*Premissas!$B$38 -> -26.196787 | ... Y26: =-Y25*Premissas!$B$38 -> -314.4024
A27: Base no fim do mês | B27: =B25+B26+B24 -> 40 | C27: =C25+C26+C24 -> 83.2 | D27: =D25+D26+D24 -> 130.276 | E27: =E25+E26+E24 -> 181.99168 | F27: =F25+F26+F24 -> 239.21251 | G27: =G25+G26+G24 -> 302.92192 | H27: =H25+H26+H24 -> 374.23982 | I27: =I25+I26+I24 -> 454.44383 | ... Y27: =Y25+Y26+Y24 -> 5172.7188
A28: Base média do mês | B28: =(B25+B27)/2 -> 20 | C28: =(C25+C27)/2 -> 61.6 | D28: =(D25+D27)/2 -> 106.738 | E28: =(E25+E27)/2 -> 156.13384 | F28: =(F25+F27)/2 -> 210.6021 | G28: =(G25+G27)/2 -> 271.06722 | H28: =(H25+H27)/2 -> 338.58087 | I28: =(I25+I27)/2 -> 414.34182 | ... Y28: =(Y25+Y27)/2 -> 4832.0908
A29: Receita bruta | B29: =B28*Premissas!$B$16 -> 458 | C29: =C28*Premissas!$B$16 -> 1410.64 | D29: =D28*Premissas!$B$16 -> 2444.3002 | E29: =E28*Premissas!$B$16 -> 3575.4649 | F29: =F28*Premissas!$B$16 -> 4822.788 | G29: =G28*Premissas!$B$16 -> 6207.4393 | H29: =H28*Premissas!$B$16 -> 7753.502 | I29: =I28*Premissas!$B$16 -> 9488.4278 | ... Y29: =Y28*Premissas!$B$16 -> 110654.88
A30: (-) Custos variáveis (impostos, taxas, IA, funil) | B30: =-B28*('Unit Economics'!$D$5-'Unit Economics'!$D$11) -> -237.57719 | C30: =-C28*('Unit Economics'!$D$5-'Unit Economics'!$D$11) -> -731.73774 | D30: =-D28*('Unit Economics'!$D$5-'Unit Economics'!$D$11) -> -1267.9257 | E30: =-E28*('Unit Economics'!$D$5-'Unit Economics'!$D$11) -> -1854.6919 | F30: =-F28*('Unit Economics'!$D$5-'Unit Economics'!$D$11) -> -2501.7127 | G30: =-G28*('Unit Economics'!$D$5-'Unit Economics'!$D$11) -> -3219.9694 | H30: =-H28*('Unit Economics'!$D$5-'Unit Economics'!$D$11) -> -4021.9546 | I30: =-I28*('Unit Economics'!$D$5-'Unit Economics'!$D$11) -> -4921.9083 | ... Y30: =-Y28*('Unit Economics'!$D$5-'Unit Economics'!$D$11) -> -57399.727
A31: Margem de contribuição | B31: =B29+B30 -> 220.42281 | C31: =C29+C30 -> 678.90226 | D31: =D29+D30 -> 1176.3745 | E31: =E29+E30 -> 1720.773 | F31: =F29+F30 -> 2321.0753 | G31: =G29+G30 -> 2987.4699 | H31: =H29+H30 -> 3731.5474 | I31: =I29+I30 -> 4566.5195 | ... Y31: =Y29+Y30 -> 53255.153
A32: (-) Custos fixos | B32: =-INDEX('Custos Fixos'!$C$26:$C$29,MATCH(B27,'Custos Fixos'!$A$26:$A$29,1)) -> -893.662 | C32: =-INDEX('Custos Fixos'!$C$26:$C$29,MATCH(C27,'Custos Fixos'!$A$26:$A$29,1)) -> -893.662 | D32: =-INDEX('Custos Fixos'!$C$26:$C$29,MATCH(D27,'Custos Fixos'!$A$26:$A$29,1)) -> -893.662 | E32: =-INDEX('Custos Fixos'!$C$26:$C$29,MATCH(E27,'Custos Fixos'!$A$26:$A$29,1)) -> -893.662 | F32: =-INDEX('Custos Fixos'!$C$26:$C$29,MATCH(F27,'Custos Fixos'!$A$26:$A$29,1)) -> -893.662 | G32: =-INDEX('Custos Fixos'!$C$26:$C$29,MATCH(G27,'Custos Fixos'!$A$26:$A$29,1)) -> -893.662 | H32: =-INDEX('Custos Fixos'!$C$26:$C$29,MATCH(H27,'Custos Fixos'!$A$26:$A$29,1)) -> -893.662 | I32: =-INDEX('Custos Fixos'!$C$26:$C$29,MATCH(I27,'Custos Fixos'!$A$26:$A$29,1)) -> -893.662 | ... Y32: =-INDEX('Custos Fixos'!$C$26:$C$29,MATCH(Y27,'Custos Fixos'!$A$26:$A$29,1)) -> -7066.39
A33: (-) Marketing (novos × % canal pago × CAC) | B33: =-B24*Premissas!$B$37*Premissas!$B$36 -> -2400 | C33: =-C24*Premissas!$B$37*Premissas!$B$36 -> -2760 | D33: =-D24*Premissas!$B$37*Premissas!$B$36 -> -3174 | E33: =-E24*Premissas!$B$37*Premissas!$B$36 -> -3650.1 | F33: =-F24*Premissas!$B$37*Premissas!$B$36 -> -4197.615 | G33: =-G24*Premissas!$B$37*Premissas!$B$36 -> -4827.2572 | H33: =-H24*Premissas!$B$37*Premissas!$B$36 -> -5551.3458 | I33: =-I24*Premissas!$B$37*Premissas!$B$36 -> -6384.0477 | ... Y33: =-Y24*Premissas!$B$37*Premissas!$B$36 -> -59739.498
A34: Resultado do mês | B34: =B31+B32+B33 -> -3073.2392 | C34: =C31+C32+C33 -> -2974.7597 | D34: =D31+D32+D33 -> -2891.2875 | E34: =E31+E32+E33 -> -2822.989 | F34: =F31+F32+F33 -> -2770.2017 | G34: =G31+G32+G33 -> -2733.4493 | H34: =H31+H32+H33 -> -2713.4604 | I34: =I31+I32+I33 -> -2711.1902 | ... Y34: =Y31+Y32+Y33 -> -13550.735
A35: Caixa acumulado | B35: =B34 -> -3073.2392 | C35: =B35+C34 -> -6047.9989 | D35: =C35+D34 -> -8939.2864 | E35: =D35+E34 -> -11762.275 | F35: =E35+F34 -> -14532.477 | G35: =F35+G34 -> -17265.926 | H35: =G35+H34 -> -19979.387 | I35: =H35+I34 -> -22690.577 | J35: =I35+J34 -> -27044.279 | ... Y35: =X35+Y34 -> -147354.65
A38: CENÁRIO OTIMISTA
A39: Novos assinantes no mês 1 | B39: 80 | D39: Crescimento mensal de novos assinantes | E39: 0.2
A40: Mês | B40: M1 | C40: M2 | D40: M3 | E40: M4 | F40: M5 | G40: M6 | H40: M7 | I40: M8 | J40: M9 | K40: M10 | L40: M11 | M40: M12 | N40: M13 | O40: M14 | P40: M15 | Q40: M16 | R40: M17 | S40: M18 | T40: M19 | U40: M20 | V40: M21 | W40: M22 | X40: M23 | Y40: M24
A41: Novos assinantes | B41: =$B$39 -> 80 | C41: =B41*(1+$E$39) -> 96 | D41: =C41*(1+$E$39) -> 115.2 | E41: =D41*(1+$E$39) -> 138.24 | F41: =E41*(1+$E$39) -> 165.888 | G41: =F41*(1+$E$39) -> 199.0656 | H41: =G41*(1+$E$39) -> 238.87872 | I41: =H41*(1+$E$39) -> 286.65446 | J41: =I41*(1+$E$39) -> 343.98536 | ... Y41: =X41*(1+$E$39) -> 5299.7898
A42: Base no início do mês | B42: =0 -> 0 | C42: =B44 -> 80 | D42: =C44 -> 170.4 | E42: =D44 -> 273.672 | F42: =E44 -> 392.75496 | G42: =F44 -> 531.15011 | H42: =G44 -> 693.0352 | I42: =H44 -> 883.40146 | J42: =I44 -> 1108.2178 | ... Y42: =X44 -> 19573.025
A43: Cancelamentos | B43: =-B42*Premissas!$B$38 -> 0 | C43: =-C42*Premissas!$B$38 -> -5.6 | D43: =-D42*Premissas!$B$38 -> -11.928 | E43: =-E42*Premissas!$B$38 -> -19.15704 | F43: =-F42*Premissas!$B$38 -> -27.492847 | G43: =-G42*Premissas!$B$38 -> -37.180508 | H43: =-H42*Premissas!$B$38 -> -48.512464 | I43: =-I42*Premissas!$B$38 -> -61.838102 | ... Y43: =-Y42*Premissas!$B$38 -> -1370.1118
A44: Base no fim do mês | B44: =B42+B43+B41 -> 80 | C44: =C42+C43+C41 -> 170.4 | D44: =D42+D43+D41 -> 273.672 | E44: =E42+E43+E41 -> 392.75496 | F44: =F42+F43+F41 -> 531.15011 | G44: =G42+G43+G41 -> 693.0352 | H44: =H42+H43+H41 -> 883.40146 | I44: =I42+I43+I41 -> 1108.2178 | ... Y44: =Y42+Y43+Y41 -> 23502.704
A45: Base média do mês | B45: =(B42+B44)/2 -> 40 | C45: =(C42+C44)/2 -> 125.2 | D45: =(D42+D44)/2 -> 222.036 | E45: =(E42+E44)/2 -> 333.21348 | F45: =(F42+F44)/2 -> 461.95254 | G45: =(G42+G44)/2 -> 612.09266 | H45: =(H42+H44)/2 -> 788.21833 | I45: =(I42+I44)/2 -> 995.80964 | ... Y45: =(Y42+Y44)/2 -> 21537.864
...

Sheet Ponto de Equilibrio
A1: Ponto de Equilíbrio e Retorno do Investimento
A2: Quantos assinantes pagam a conta, e em quanto tempo o dinheiro investido volta.
A4: Indicador | B4: Valor | C4: Leitura
A5: PONTO DE EQUILÍBRIO OPERACIONAL (sem marketing)
A6: Margem de contribuição média por assinante (R$/mês) | B6: ='Unit Economics'!$D$11 -> 11.021141 | C6: Vem da aba Unit Economics.
A7: Custo fixo mensal na faixa inicial (até 500 assinantes) | B7: ='Custos Fixos'!$C$26 -> 893.662
A8: Assinantes necessários para cobrir os custos fixos | B8: =IF(B6<=0,0,ROUNDUP(B7/B6,0)) -> 82 | C8: Este é o número mágico: a partir daqui o sistema se paga sozinho, sem contar marketing.
A9: Receita mensal nesse ponto | B9: =B8*Premissas!$B$16 -> 1877.8
A11: PONTO DE EQUILÍBRIO COM MARKETING ATIVO
A12: Orçamento mensal de marketing (R$) | B12: 12000 | C12: Edite conforme o plano de aquisição.
A13: Assinantes necessários para cobrir custos fixos + marketing | B13: =IF(B6<=0,0,ROUNDUP((B7+B12)/B6,0)) -> 1170 | C13: Com marketing ligado, a barra sobe muito. Por isso marketing só entra depois do produto pronto e do canal validado.
A15: RETORNO DO INVESTIMENTO
A16: Investimento inicial (desembolso pré-lançamento) | B16: ='Investimento Inicial'!$B$20 -> 35256.7
A17: Resultado mensal no cenário realista, mês 24 | B17: ='Projecao 24 meses'!Y34 -> -13550.735
A18: Caixa acumulado do cenário realista em 24 meses | B18: ='Projecao 24 meses'!Y35 -> -147354.65
A19: O investimento se paga em 24 meses? | B19: =IF(B18>=B16,"SIM","NÃO") -> NÃO | C19: Compara o caixa gerado com o desembolso inicial. Não inclui o valor do seu trabalho de desenvolvimento.
A21: TESTE DE SENSIBILIDADE — o que mais muda o resultado
A22: Variável | B22: Impacto na margem por assinante | C22: Comentário
A23: Reduzir o custo de IA em 50% (cache agressivo, conteúdo pré-gerado) | B23: =Premissas!$B$28*0.5*Premissas!$B$15+Premissas!$B$30*0.5*(1-Premissas!$B$15) -> 3.3045197 | C23: Ganho direto por assinante, todo mês. É a alavanca mais controlável.
A24: Cobrar 100% pela web, eliminando a comissão das lojas | B24: =Premissas!$B$16*Premissas!$B$10*Premissas!$B$9 -> 1.0305 | C24: Ganho por assinante. Exige levar o usuário ao site para assinar.
A25: Reduzir o churn de 7% para 5% | B25: ='Unit Economics'!$D$11*(1/0.05-1/Premissas!$B$38) -> 62.977947 | C25: Ganho de LTV por assinante (valor total, não mensal). O maior salto de todos.
A27: METAS PARA O MODELO FECHAR (LTV/CAC = 3,0x)
A28: CAC máximo aceitável com a margem atual (R$) | B28: ='Unit Economics'!$D$16/3 -> 52.481622 | C28: Acima disso, cada assinante conquistado por mídia paga destrói caixa.
A29: Churn máximo aceitável com a margem e o CAC atuais | B29: =IF(Premissas!$B$36=0,0,'Unit Economics'!$D$11/(3*Premissas!$B$36)) -> 0.03061428 | C29: Se o churn real ficar acima disso, nenhuma otimização de custo salva a aquisição paga.
A30: Margem por assinante necessária (R$/mês) | B30: =3*Premissas!$B$36*Premissas!$B$38 -> 25.2 | C30: Compare com a margem atual e com o ARPU. Se for maior que o ARPU, o preço atual não comporta mídia paga.
A31: Margem atual por assinante (R$/mês) | B31: ='Unit Economics'!$D$11 -> 11.021141 | C31: Vem da aba Unit Economics.
A32: Veredito | B32: =IF(B30<=B31,"O modelo fecha com mídia paga.",IF(B30>Premissas!$B$16,"O preço atual NÃO comporta mídia paga: a margem necessária supera a própria receita. Cresça por canal orgânico, parcerias e white label, ou reveja preço e churn.","O preço comporta, mas só se os custos variáveis (IA e comissão de loja) caírem.")) -> O preço atual NÃO comporta mídia paga: a margem necessária supera a própria receita. Cresça por canal orgânico, parcerias e white label, ou reveja preço e churn.

Sheet Fontes
A1: Fontes dos Números de Mercado
A2: Consultadas em 27 de julho de 2026.
A4: Item | B4: Valor usado | C4: Fonte
A5: Câmbio USD/BRL | B5: R$ 5,08 | C5: Investing.com — cotação USD/BRL em 27/07/2026
A6: Supabase Pro | B6: US$ 25/mês | C6: Documentação de preços do Supabase; inclui US$ 10 de crédito de compute (instância Micro)
A7: Supabase Team | B7: US$ 599/mês | C7: Plano Team do Supabase, para a faixa acima de 10 mil assinantes
A8: Vercel Pro | B8: US$ 20/assento/mês | C8: Preços da Vercel; inclui 1 TB de transferência, excedente a US$ 0,15/GB
A9: Apple Developer Program | B9: US$ 99/ano | C9: developer.apple.com/programs — renovação anual
A10: Google Play Console | B10: US$ 25 (único) | C10: support.google.com — taxa única de registro, sem renovação
A11: Comissão das lojas de app | B11: 15% | C11: Apple e Google Small Business Program, para faturamento abaixo de US$ 1 mi/ano
A12: Gateway de pagamento | B12: 3,99% + 0,4% | C12: Stripe Brasil — transação nacional + adicional de assinatura recorrente
A13: Claude Haiku 4.5 (modelo econômico) | B13: US$ 1 / US$ 5 por 1M tokens | C13: Tabela de preços da API da Anthropic, julho/2026
A14: Claude Sonnet (modelo avançado) | B14: US$ 3 / US$ 15 por 1M tokens | C14: Tabela de preços da API da Anthropic, julho/2026
A15: Cache de prompt | B15: até 90% de economia na entrada | C15: Documentação da Anthropic sobre prompt caching
... A17: Simples Nacional — Anexo III | B17: 6% na 1ª faixa | C17: Legislação do Simples Nacional. Confirme o enquadramento com seu contador
A19: Preços de nuvem e de API mudam com frequência. Reconfirme antes de usar este modelo em qualquer apresentação externa.
